2019-02-12 21:21:04,569 INFO: Microblog startup [in D:\flask_proj\microblog\app\__init__.py:41]
2019-02-12 21:30:59,801 INFO: Microblog startup [in D:\flask_proj\microblog\app\__init__.py:41]
2019-02-12 21:31:08,817 INFO: Microblog startup [in D:\flask_proj\microblog\app\__init__.py:41]
2019-02-12 22:11:02,815 INFO: Microblog startup [in D:\flask_proj\microblog\app\__init__.py:41]
2019-02-12 22:11:39,392 INFO: Microblog startup [in D:\flask_proj\microblog\app\__init__.py:41]
2019-02-12 22:26:13,437 INFO: Microblog startup [in D:\flask_proj\microblog\app\__init__.py:41]
2019-02-14 21:33:57,628 INFO: Microblog startup [in D:\flask_proj\microblog\app\__init__.py:41]
2019-02-14 21:34:48,422 ERROR: Exception on / [POST] [in c:\users\yi\anaconda3\envs\flask\lib\site-packages\flask\app.py:1761]
Traceback (most recent call last):
  File "c:\users\yi\anaconda3\envs\flask\lib\site-packages\flask\app.py", line 2292, in wsgi_app
    response = self.full_dispatch_request()
  File "c:\users\yi\anaconda3\envs\flask\lib\site-packages\flask\app.py", line 1815, in full_dispatch_request
    rv = self.handle_user_exception(e)
  File "c:\users\yi\anaconda3\envs\flask\lib\site-packages\flask\app.py", line 1718, in handle_user_exception
    reraise(exc_type, exc_value, tb)
  File "c:\users\yi\anaconda3\envs\flask\lib\site-packages\flask\_compat.py", line 35, in reraise
    raise value
  File "c:\users\yi\anaconda3\envs\flask\lib\site-packages\flask\app.py", line 1813, in full_dispatch_request
    rv = self.dispatch_request()
  File "c:\users\yi\anaconda3\envs\flask\lib\site-packages\flask\app.py", line 1799, in dispatch_request
    return self.view_functions[rule.endpoint](**req.view_args)
  File "c:\users\yi\anaconda3\envs\flask\lib\site-packages\flask_login\utils.py", line 261, in decorated_view
    return func(*args, **kwargs)
  File "D:\flask_proj\microblog\app\routes.py", line 15, in index
    post = Post(body=form.post.data, author=current_user)
NameError: name 'Post' is not defined
2019-02-14 21:35:37,507 INFO: Microblog startup [in D:\flask_proj\microblog\app\__init__.py:41]
2019-02-14 21:36:40,156 INFO: Microblog startup [in D:\flask_proj\microblog\app\__init__.py:41]
2019-02-14 21:38:39,269 INFO: Microblog startup [in D:\flask_proj\microblog\app\__init__.py:41]
2019-02-14 21:47:35,512 INFO: Microblog startup [in D:\flask_proj\microblog\app\__init__.py:41]
2019-02-14 21:49:04,610 INFO: Microblog startup [in D:\flask_proj\microblog\app\__init__.py:41]
2019-02-16 21:49:08,908 INFO: Microblog startup [in D:\flask_proj\microblog\app\__init__.py:41]
2019-02-16 21:49:26,139 ERROR: Exception on / [GET] [in c:\users\yi\anaconda3\envs\flask\lib\site-packages\flask\app.py:1761]
Traceback (most recent call last):
  File "c:\users\yi\anaconda3\envs\flask\lib\site-packages\flask\app.py", line 2292, in wsgi_app
    response = self.full_dispatch_request()
  File "c:\users\yi\anaconda3\envs\flask\lib\site-packages\flask\app.py", line 1815, in full_dispatch_request
    rv = self.handle_user_exception(e)
  File "c:\users\yi\anaconda3\envs\flask\lib\site-packages\flask\app.py", line 1718, in handle_user_exception
    reraise(exc_type, exc_value, tb)
  File "c:\users\yi\anaconda3\envs\flask\lib\site-packages\flask\_compat.py", line 35, in reraise
    raise value
  File "c:\users\yi\anaconda3\envs\flask\lib\site-packages\flask\app.py", line 1813, in full_dispatch_request
    rv = self.dispatch_request()
  File "c:\users\yi\anaconda3\envs\flask\lib\site-packages\flask\app.py", line 1799, in dispatch_request
    return self.view_functions[rule.endpoint](**req.view_args)
  File "c:\users\yi\anaconda3\envs\flask\lib\site-packages\flask_login\utils.py", line 261, in decorated_view
    return func(*args, **kwargs)
  File "D:\flask_proj\microblog\app\routes.py", line 15, in index
    posts = current_user.followed_posts().paginate(page, app.config['POST_PER_PAGE'], False)
KeyError: 'POST_PER_PAGE'
2019-02-16 21:50:19,952 INFO: Microblog startup [in D:\flask_proj\microblog\app\__init__.py:41]
2019-02-16 22:18:19,674 INFO: Microblog startup [in D:\flask_proj\microblog\app\__init__.py:41]
2019-02-16 22:53:22,927 INFO: Microblog startup [in D:\flask_proj\microblog\app\__init__.py:43]
2019-02-17 08:36:13,699 INFO: Microblog startup [in D:\flask_proj\microblog\app\__init__.py:43]
2019-02-17 09:42:37,639 INFO: Microblog startup [in D:\flask_proj\microblog\app\__init__.py:43]
2019-02-17 09:42:57,886 ERROR: Exception on /reset_password_request [GET] [in c:\users\yi\anaconda3\envs\flask\lib\site-packages\flask\app.py:1761]
Traceback (most recent call last):
  File "c:\users\yi\anaconda3\envs\flask\lib\site-packages\flask\app.py", line 2292, in wsgi_app
    response = self.full_dispatch_request()
  File "c:\users\yi\anaconda3\envs\flask\lib\site-packages\flask\app.py", line 1815, in full_dispatch_request
    rv = self.handle_user_exception(e)
  File "c:\users\yi\anaconda3\envs\flask\lib\site-packages\flask\app.py", line 1718, in handle_user_exception
    reraise(exc_type, exc_value, tb)
  File "c:\users\yi\anaconda3\envs\flask\lib\site-packages\flask\_compat.py", line 35, in reraise
    raise value
  File "c:\users\yi\anaconda3\envs\flask\lib\site-packages\flask\app.py", line 1813, in full_dispatch_request
    rv = self.dispatch_request()
  File "c:\users\yi\anaconda3\envs\flask\lib\site-packages\flask\app.py", line 1799, in dispatch_request
    return self.view_functions[rule.endpoint](**req.view_args)
  File "D:\flask_proj\microblog\app\routes.py", line 148, in reset_password_request
    return render_template('reset_password_request.html', title='Reset_Password', form=form)
  File "c:\users\yi\anaconda3\envs\flask\lib\site-packages\flask\templating.py", line 135, in render_template
    context, ctx.app)
  File "c:\users\yi\anaconda3\envs\flask\lib\site-packages\flask\templating.py", line 117, in _render
    rv = template.render(context)
  File "c:\users\yi\anaconda3\envs\flask\lib\site-packages\jinja2\asyncsupport.py", line 76, in render
    return original_render(self, *args, **kwargs)
  File "c:\users\yi\anaconda3\envs\flask\lib\site-packages\jinja2\environment.py", line 1008, in render
    return self.environment.handle_exception(exc_info, True)
  File "c:\users\yi\anaconda3\envs\flask\lib\site-packages\jinja2\environment.py", line 780, in handle_exception
    reraise(exc_type, exc_value, tb)
  File "c:\users\yi\anaconda3\envs\flask\lib\site-packages\jinja2\_compat.py", line 37, in reraise
    raise value.with_traceback(tb)
  File "D:\flask_proj\microblog\app\templates\reset_password_request.html", line 1, in top-level template code
    {% extends "base.html" %}
  File "D:\flask_proj\microblog\app\templates\base.html", line 31, in top-level template code
    {% block content %}{% endblock %}
  File "D:\flask_proj\microblog\app\templates\reset_password_request.html", line 7, in block "content"
    {{ form.email.label }}<br>
  File "c:\users\yi\anaconda3\envs\flask\lib\site-packages\jinja2\environment.py", line 430, in getattr
    return getattr(obj, attribute)
jinja2.exceptions.UndefinedError: 'app.forms.ResetPasswordRequestForm object' has no attribute 'email'
2019-02-17 09:44:48,619 ERROR: Exception on /reset_password_request [GET] [in c:\users\yi\anaconda3\envs\flask\lib\site-packages\flask\app.py:1761]
Traceback (most recent call last):
  File "c:\users\yi\anaconda3\envs\flask\lib\site-packages\flask\app.py", line 2292, in wsgi_app
    response = self.full_dispatch_request()
  File "c:\users\yi\anaconda3\envs\flask\lib\site-packages\flask\app.py", line 1815, in full_dispatch_request
    rv = self.handle_user_exception(e)
  File "c:\users\yi\anaconda3\envs\flask\lib\site-packages\flask\app.py", line 1718, in handle_user_exception
    reraise(exc_type, exc_value, tb)
  File "c:\users\yi\anaconda3\envs\flask\lib\site-packages\flask\_compat.py", line 35, in reraise
    raise value
  File "c:\users\yi\anaconda3\envs\flask\lib\site-packages\flask\app.py", line 1813, in full_dispatch_request
    rv = self.dispatch_request()
  File "c:\users\yi\anaconda3\envs\flask\lib\site-packages\flask\app.py", line 1799, in dispatch_request
    return self.view_functions[rule.endpoint](**req.view_args)
  File "D:\flask_proj\microblog\app\routes.py", line 148, in reset_password_request
    return render_template('reset_password_request.html', title='Reset_Password', form=form)
  File "c:\users\yi\anaconda3\envs\flask\lib\site-packages\flask\templating.py", line 135, in render_template
    context, ctx.app)
  File "c:\users\yi\anaconda3\envs\flask\lib\site-packages\flask\templating.py", line 117, in _render
    rv = template.render(context)
  File "c:\users\yi\anaconda3\envs\flask\lib\site-packages\jinja2\asyncsupport.py", line 76, in render
    return original_render(self, *args, **kwargs)
  File "c:\users\yi\anaconda3\envs\flask\lib\site-packages\jinja2\environment.py", line 1008, in render
    return self.environment.handle_exception(exc_info, True)
  File "c:\users\yi\anaconda3\envs\flask\lib\site-packages\jinja2\environment.py", line 780, in handle_exception
    reraise(exc_type, exc_value, tb)
  File "c:\users\yi\anaconda3\envs\flask\lib\site-packages\jinja2\_compat.py", line 37, in reraise
    raise value.with_traceback(tb)
  File "D:\flask_proj\microblog\app\templates\reset_password_request.html", line 1, in top-level template code
    {% extends "base.html" %}
  File "D:\flask_proj\microblog\app\templates\base.html", line 31, in top-level template code
    {% block content %}{% endblock %}
  File "D:\flask_proj\microblog\app\templates\reset_password_request.html", line 7, in block "content"
    {{ form.email.label }}<br>
  File "c:\users\yi\anaconda3\envs\flask\lib\site-packages\jinja2\environment.py", line 430, in getattr
    return getattr(obj, attribute)
jinja2.exceptions.UndefinedError: 'app.forms.ResetPasswordRequestForm object' has no attribute 'email'
2019-02-17 09:45:28,005 INFO: Microblog startup [in D:\flask_proj\microblog\app\__init__.py:43]
